<?xml version="1.0" ?>
<!-- =================================================================================== -->
<!-- |    This document was autogenerated by xacro from iiwa7.urdf.xacro               | -->
<!-- |    EDITING THIS FILE BY HAND IS NOT RECOMMENDED                                 | -->
<!-- =================================================================================== -->
<!-- top level -->
<robot name="iiwa7">
  <material name="orange">
    <color rgba="1.0 0.42 0.04 1.0"/>
  </material>
  <material name="white">
    <color rgba="1.0 1.0 1.0 1.0"/>
  </material>
  <material name="silver">
    <color rgba="0.7 0.7 0.7 1.0"/>
  </material>
  <!-- fix to world -->
  <link name="world"/>
  <!--joint between {parent} and link_0-->
  <joint name="world_lbr_joint" type="fixed">
    <parent link="world"/>
    <child link="lbr_link_0"/>
  </joint>
  <link name="lbr_link_0">
    <inertial>
      <origin rpy="0 0 0" xyz="-0.01283618494463161 4.904567390585061e-08 0.07010682239932087"/>
      <mass value="4.861279"/>
      <inertia ixx="0.017901" ixy="0.000000" ixz="0.000771" iyy="0.022356" iyz="-0.000000" izz="0.021346"/>
    </inertial>
    <visual>
      <origin rpy="0 0 0" xyz="0 0 0"/>
      <geometry>
        <mesh filename="package://visual/link_0.stl"/>
      </geometry>
      <material name="silver"/>
    </visual>
    <collision>
      <origin rpy="0 0 0" xyz="0 0 0"/>
      <geometry>
        <mesh filename="package://collision/link_0.stl"/>
      </geometry>
    </collision>
  </link>
  <joint name="lbr_joint_0" type="revolute">
    <origin rpy="0 0 0" xyz="0.0 0.0 0.1475"/>
    <parent link="lbr_link_0"/>
    <child link="lbr_link_1"/>
    <axis xyz="0.0 0.0 1.0"/>
    <limit effort="300" lower="-2.9670597283903604" upper="2.9670597283903604" velocity="10"/>
    <dynamics damping="10.0" friction="0.1"/>
  </joint>
  <link name="lbr_link_1">
    <inertial>
      <origin rpy="0 0 0" xyz="4.9980243666546455e-08 -0.0347335291089292 0.12351608478142942"/>
      <mass value="3.400745"/>
      <inertia ixx="0.021502" ixy="-0.000000" ixz="0.000000" iyy="0.020512" iyz="0.003828" izz="0.007587"/>
    </inertial>
    <visual>
      <origin rpy="0 0 0" xyz="-0.0 0.0 -0.1475"/>
      <geometry>
        <mesh filename="package://visual/link_1.stl"/>
      </geometry>
      <material name="orange"/>
    </visual>
    <collision>
      <origin rpy="0 0 0" xyz="-0.0 0.0 -0.1475"/>
      <geometry>
        <mesh filename="package://collision/link_1.stl"/>
      </geometry>
    </collision>
  </link>
  <joint name="lbr_joint_1" type="revolute">
    <origin rpy="0 0 0" xyz="-0.0 -0.0105 0.193"/>
    <parent link="lbr_link_1"/>
    <child link="lbr_link_2"/>
    <axis xyz="0.0 1.0 0.0"/>
    <limit effort="300" lower="-2.0943951023931953" upper="2.0943951023931953" velocity="10"/>
    <dynamics damping="10.0" friction="0.1"/>
  </joint>
  <link name="lbr_link_2">
    <inertial>
      <origin rpy="0 0 0" xyz="4.0558428502019873e-08 0.04491581578298656 0.06732515284873997"/>
      <mass value="3.430184"/>
      <inertia ixx="0.021455" ixy="-0.000000" ixz="0.000000" iyy="0.020444" iyz="0.003570" izz="0.007671"/>
    </inertial>
    <visual>
      <origin rpy="0 0 0" xyz="0.0 0.0105 -0.3405"/>
      <geometry>
        <mesh filename="package://visual/link_2.stl"/>
      </geometry>
      <material name="orange"/>
    </visual>
    <collision>
      <origin rpy="0 0 0" xyz="0.0 0.0105 -0.3405"/>
      <geometry>
        <mesh filename="package://collision/link_2.stl"/>
      </geometry>
    </collision>
  </link>
  <joint name="lbr_joint_2" type="revolute">
    <origin rpy="0 0 0" xyz="0.0 0.0105 0.1745"/>
    <parent link="lbr_link_2"/>
    <child link="lbr_link_3"/>
    <axis xyz="0.0 0.0 1.0"/>
    <limit effort="300" lower="-2.9670597283903604" upper="2.9670597283903604" velocity="10"/>
    <dynamics damping="10.0" friction="0.1"/>
  </joint>
  <link name="lbr_link_3">
    <inertial>
      <origin rpy="0 0 0" xyz="-5.881068064938613e-09 0.02956361869175564 0.1365034185434154"/>
      <mass value="3.995443"/>
      <inertia ixx="0.031559" ixy="-0.000000" ixz="0.000000" iyy="0.029960" iyz="-0.006133" izz="0.009574"/>
    </inertial>
    <visual>
      <origin rpy="0 0 0" xyz="0.0 0.0 -0.515"/>
      <geometry>
        <mesh filename="package://visual/link_3.stl"/>
      </geometry>
      <material name="orange"/>
    </visual>
    <collision>
      <origin rpy="0 0 0" xyz="0.0 0.0 -0.515"/>
      <geometry>
        <mesh filename="package://collision/link_3.stl"/>
      </geometry>
    </collision>
  </link>
  <joint name="lbr_joint_3" type="revolute">
    <origin rpy="0 0 0" xyz="0.0 0.0105 0.2255"/>
    <parent link="lbr_link_3"/>
    <child link="lbr_link_4"/>
    <axis xyz="0.0 -1.0 0.0"/>
    <limit effort="300" lower="-2.0943951023931953" upper="2.0943951023931953" velocity="10"/>
    <dynamics damping="10.0" friction="0.1"/>
  </joint>
  <link name="lbr_link_4">
    <inertial>
      <origin rpy="0 0 0" xyz="-4.1344813497116265e-08 -0.044916218629510306 0.06732501840381"/>
      <mass value="3.430182"/>
      <inertia ixx="0.021454" ixy="0.000000" ixz="-0.000000" iyy="0.020443" iyz="-0.003570" izz="0.007670"/>
    </inertial>
    <visual>
      <origin rpy="0 0 0" xyz="0.0 -0.0105 -0.7405"/>
      <geometry>
        <mesh filename="package://visual/link_4.stl"/>
      </geometry>
      <material name="orange"/>
    </visual>
    <collision>
      <origin rpy="0 0 0" xyz="0.0 -0.0105 -0.7405"/>
      <geometry>
        <mesh filename="package://collision/link_4.stl"/>
      </geometry>
    </collision>
  </link>
  <joint name="lbr_joint_4" type="revolute">
    <origin rpy="0 0 0" xyz="0.0 -0.0105 0.1745"/>
    <parent link="lbr_link_4"/>
    <child link="lbr_link_5"/>
    <axis xyz="0.0 0.0 1.0"/>
    <limit effort="300" lower="-2.9670597283903604" upper="2.9670597283903604" velocity="10"/>
    <dynamics damping="10.0" friction="0.1"/>
  </joint>
  <link name="lbr_link_5">
    <inertial>
      <origin rpy="0 0 0" xyz="2.416002990197734e-08 -0.021386601078580914 0.085468591256322"/>
      <mass value="2.131557"/>
      <inertia ixx="0.012684" ixy="-0.000000" ixz="-0.000000" iyy="0.010952" iyz="0.003889" izz="0.005624"/>
    </inertial>
    <visual>
      <origin rpy="0 0 0" xyz="0.0 0.0 -0.915"/>
      <geometry>
        <mesh filename="package://visual/link_5.stl"/>
      </geometry>
      <material name="orange"/>
    </visual>
    <collision>
      <origin rpy="0 0 0" xyz="0.0 0.0 -0.915"/>
      <geometry>
        <mesh filename="package://collision/link_5.stl"/>
      </geometry>
    </collision>
  </link>
  <joint name="lbr_joint_5" type="revolute">
    <origin rpy="0 0 0" xyz="0.0 -0.0707 0.2255"/>
    <parent link="lbr_link_5"/>
    <child link="lbr_link_6"/>
    <axis xyz="0.0 1.0 0.0"/>
    <limit effort="300" lower="-2.0943951023931953" upper="2.0943951023931953" velocity="10"/>
    <dynamics damping="10.0" friction="0.1"/>
  </joint>
  <link name="lbr_link_6">
    <inertial>
      <origin rpy="0 0 0" xyz="-9.07120004240837e-08 0.0709871260349443 0.002115721730276743"/>
      <mass value="2.311862"/>
      <inertia ixx="0.006412" ixy="-0.000000" ixz="-0.000000" iyy="0.006166" iyz="0.000314" izz="0.004459"/>
    </inertial>
    <visual>
      <origin rpy="0 0 0" xyz="0.0 0.0707 -1.1405"/>
      <geometry>
        <mesh filename="package://visual/link_6.stl"/>
      </geometry>
      <material name="orange"/>
    </visual>
    <collision>
      <origin rpy="0 0 0" xyz="0.0 0.0707 -1.1405"/>
      <geometry>
        <mesh filename="package://collision/link_6.stl"/>
      </geometry>
    </collision>
  </link>
  <joint name="lbr_joint_6" type="revolute">
    <origin rpy="0 0 0" xyz="0.0 0.0705 0.0909"/>
    <parent link="lbr_link_6"/>
    <child link="lbr_link_7"/>
    <axis xyz="0.0 0.0 1.0"/>
    <limit effort="300" lower="-3.0543261909900763" upper="3.0543261909900763" velocity="10"/>
    <dynamics damping="10.0" friction="0.1"/>
  </joint>
  <link name="lbr_link_7">
    <inertial>
      <origin rpy="0 0 0" xyz="4.535378460217862e-06 -1.7615872956281168e-08 0.009883270430701696"/>
      <mass value="0.338747"/>
      <inertia ixx="0.000250" ixy="-0.000000" ixz="-0.000000" iyy="0.000245" iyz="0.000000" izz="0.000406"/>
    </inertial>
    <visual>
      <origin rpy="0 0 0" xyz="0.0 0.0002 -1.2314"/>
      <geometry>
        <mesh filename="package://visual/link_7.stl"/>
      </geometry>
      <material name="silver"/>
    </visual>
    <collision>
      <origin rpy="0 0 0" xyz="0.0 0.0002 -1.2314"/>
      <geometry>
        <mesh filename="package://collision/link_7.stl"/>
      </geometry>
    </collision>
  </link>
  <joint name="lbr_joint_ee" type="fixed">
    <parent link="lbr_link_7"/>
    <child link="lbr_link_ee"/>
    <origin rpy="0 0 0" xyz="0 0 0.035"/>
  </joint>
  <link name="lbr_link_ee">
        </link>
  <!-- ros_control-plugin -->
  <gazebo>
    <plugin filename="libgazebo_ros2_control.so" name="gazebo_ros2_control">
      <parameters>/home/jens/workspace/ros_ur_driver/install/lbr_bringup/share/lbr_bringup/config/lbr_controllers.yml</parameters>
      <robotNamespace>/lbr</robotNamespace>
    </plugin>
  </gazebo>
  <!-- link 0 -->
  <gazebo reference="lbr_link_0">
    <mu1>0.2</mu1>
    <mu2>0.2</mu2>
    <material>Gazebo/Grey</material>
  </gazebo>
  <!-- link 1 -->
  <gazebo reference="lbr_link_1">
    <mu1>0.2</mu1>
    <mu2>0.2</mu2>
    <material>Gazebo/Orange</material>
  </gazebo>
  <!-- link 2 -->
  <gazebo reference="lbr_link_2">
    <mu1>0.2</mu1>
    <mu2>0.2</mu2>
    <material>Gazebo/Orange</material>
  </gazebo>
  <!-- link 3 -->
  <gazebo reference="lbr_link_3">
    <mu1>0.2</mu1>
    <mu2>0.2</mu2>
    <material>Gazebo/Orange</material>
  </gazebo>
  <!-- link 4 -->
  <gazebo reference="lbr_link_4">
    <mu1>0.2</mu1>
    <mu2>0.2</mu2>
    <material>Gazebo/Orange</material>
  </gazebo>
  <!-- link 5 -->
  <gazebo reference="lbr_link_5">
    <mu1>0.2</mu1>
    <mu2>0.2</mu2>
    <material>Gazebo/Orange</material>
  </gazebo>
  <!-- link 6 -->
  <gazebo reference="lbr_link_6">
    <mu1>0.2</mu1>
    <mu2>0.2</mu2>
    <material>Gazebo/Orange</material>
  </gazebo>
  <!-- link 7 -->
  <gazebo reference="lbr_link_7">
    <mu1>0.2</mu1>
    <mu2>0.2</mu2>
    <material>Gazebo/Grey</material>
  </gazebo>
  <!-- arg for control mode -->
  <ros2_control name="lbr_hardware_interface" type="system">
    <hardware>
      <plugin>gazebo_ros2_control/GazeboSystem</plugin>
    </hardware>
    <!-- define lbr specific state interfaces as sensor, see https://github.com/ros-controls/roadmap/blob/master/design_drafts/components_architecture_and_urdf_examples.md -->
    <sensor name="lbr_state">
      <!-- see KUKA::FRI::LBRState -->
      <state_interface name="sample_time"/>
      <state_interface name="time_stamp_sec"/>
      <state_interface name="time_stamp_nano_sec"/>
    </sensor>
    <!-- define joints and command/state interfaces for each joint -->
    <joint name="lbr_joint_0">
      <command_interface name="position">
        <!-- better to use radians as min max first -->
        <param name="min">-1</param>
        <param name="max"> 1</param>
      </command_interface>
      <command_interface name="effort">
        <param name="min">-1</param>
        <param name="max"> 1</param>
      </command_interface>
      <state_interface name="position"/>
      <state_interface name="effort"/>
      <state_interface name="external_torque"/>
    </joint>
    <joint name="lbr_joint_1">
      <command_interface name="position">
        <param name="min">-1</param>
        <param name="max"> 1</param>
      </command_interface>
      <command_interface name="effort">
        <param name="min">-1</param>
        <param name="max"> 1</param>
      </command_interface>
      <state_interface name="position"/>
      <state_interface name="effort"/>
      <state_interface name="external_torque"/>
    </joint>
    <joint name="lbr_joint_2">
      <command_interface name="position">
        <param name="min">-1</param>
        <param name="max"> 1</param>
      </command_interface>
      <command_interface name="effort">
        <param name="min">-1</param>
        <param name="max"> 1</param>
      </command_interface>
      <state_interface name="position"/>
      <state_interface name="effort"/>
      <state_interface name="external_torque"/>
    </joint>
    <joint name="lbr_joint_3">
      <command_interface name="position">
        <param name="min">-1</param>
        <param name="max"> 1</param>
      </command_interface>
      <command_interface name="effort">
        <param name="min">-1</param>
        <param name="max"> 1</param>
      </command_interface>
      <state_interface name="position"/>
      <state_interface name="effort"/>
      <state_interface name="external_torque"/>
    </joint>
    <joint name="lbr_joint_4">
      <command_interface name="position">
        <param name="min">-1</param>
        <param name="max"> 1</param>
      </command_interface>
      <command_interface name="effort">
        <param name="min">-1</param>
        <param name="max"> 1</param>
      </command_interface>
      <state_interface name="position"/>
      <state_interface name="effort"/>
      <state_interface name="external_torque"/>
    </joint>
    <joint name="lbr_joint_5">
      <command_interface name="position">
        <param name="min">-1</param>
        <param name="max"> 1</param>
      </command_interface>
      <command_interface name="effort">
        <param name="min">-1</param>
        <param name="max"> 1</param>
      </command_interface>
      <state_interface name="position"/>
      <state_interface name="effort"/>
      <state_interface name="external_torque"/>
    </joint>
    <joint name="lbr_joint_6">
      <command_interface name="position">
        <param name="min">-1</param>
        <param name="max"> 1</param>
      </command_interface>
      <command_interface name="effort">
        <param name="min">-1</param>
        <param name="max"> 1</param>
      </command_interface>
      <state_interface name="position"/>
      <state_interface name="effort"/>
      <state_interface name="external_torque"/>
    </joint>
  </ros2_control>
</robot>
